Workbook

Sheet DESCRICAO PRODUTO
A1: CODIGO | B1: DESCRIÇÃO | C1: MODELO
A2: 0645-01 | B2: CAIXA AMPLIFICADA MCO-14 BIVOLT . | C2: MCO 14
A3: 0685-01 | B3: CAIXA AMPLIFICADA CM-400 BIVOLT . | C3: CM 400
A4: 0685-02 | B4: CAIXA AMPLIFICADA CM-400 BIVOLT . | C4: CM 400
A5: 0685-03 | B5: CAIXA AMPLIFICADA CM-400 BIVOLT . | C5: CM 400
A6: 0685-04 | B6: CAIXA AMPLIFICADA CM-400 BIVOLT . | C6: CM 400
A7: 1455-01 | B7: DVD D-22 BIVOLT . | C7: DVD
A8: 1705-01 | B8: CAIXA AMPLIFICADA CM-500 BIVOLT. | C8: CM 500
A9: 1705-02 | B9: CAIXA AMPLIFICADA CM-500 BIVOLT . | C9: CM 500
A10: 2108-01 | B10: CAIXA AMPLIFICADA CM-250 BIVOLT . | C10: CM 250
A11: 2108-02 | B11: CAIXA AMPLIFICADA CM-250 BIVOLT . | C11: CM 250
A12: 2108-03 | B12: CAIXA AMPLIFICADA CM-250 BIVOLT . | C12: CM 250
... A136: 7040-01 | B136: CAIXA AMPLIFICADA CM-220-N BIV. | C136: CM 220 N

Sheet DINAMICA
A1: STATUS | B1: (Tudo)
A2: MODELO DO PRODUTO | B2: (Tudo)
A4: DATA COMPRAS | B4: CODIGO DA EMBALAGEM | C4: DESCRIÇAO DA EMBALAGEM | D4: CODIGO DO PRODUTO | E4: QUANTIDADE SOLICITADA
A5: TBC | B5: 040122-0014-01 | C5: CX DE EMBALAGEM INDIVIDUAL GOOGLE 75 | D5: 5122-01 | E5: 1
A6: TBC | B6: 1114-42 | C6: EMBALAGEM INDIVIDUAL DVD D-15 | D6: 4860-01 | E6: 15
A7: TBC | B7: 1114-51 | C7: CAIXA EMBALAGEM INDIVIDUAL DVD D-18 | D7: 6014-01 | E7: 3
A8: TBC | B8: 1116-32 | C8: CAIXA EMBALAGEM COLETIVA DVD D-14 | D8: 6010-01 | E8: 1
A9: TBC | B9: 1116-33 | C9: CAIXA EMBALAGEM INDIVIDUAL DVD D-14 | D9: 6010-01 | E9: 1
A10: TBC | B10: 1116-38 | C10: EMBALAGEM COLETIVA DVD D-15 | D10: 4860-01 | E10: 3
A11: TBC | B11: 1116-38 | C11: EMBALAGEM COLETIVA DVD D-15 | D11: 6014-01 | E11: 1
A12: TBC | B12: 1116-59 | C12: CAIXA EMBALAGEM INDIVIDUAL TB-14 | D12: 8821-01 | E12: 2
A13: TBC | B13: 1117-57 | C13: CAIXA DE EMBALAGEM INDIVIDUAL NTB-12G | D13: 7754-01 | E13: 1
A14: TBC | B14: 1118-01 | C14: CAIXA EMBALAGEM INDIVIDUAL TB-18 | D14: 8814-01 | E14: 3
A15: TBC | B15: 2010-60 | C15: EMBALAGEM INDIVIDUAL MCO-14 | D15: 0645-01 | E15: 169
A16: TBC | B16: 2016-78 | C16: EMBALAGEM IND NBX-13 - REV.01 | D16: 5161-01 | E16: 218
... A31: TBC | B31: 2019-93 | C31: EMBALAGEM INDIVIDUAL DVD D-22 | D31: 1455-01 | E31: 31
A32: TBC Total | E32: 1077
A33: 46078 | B33: 030625-0005-01 | C33: ROTULO DE IDENTIFICAÇAO T1W | D33: 5116-01 | E33: 346
A34: 46078 | B34: 040125-0023-01 | C34: CX DE EMBALAGEM INDIVIDUAL T1W | D34: 5116-01 | E34: 173
A35: 25/02/2026 Total | E35: 519
A36: 46091 | B36: 030623-0001-02 | C36: RÓTULO DE IDENTIF BLACK 21L 450X250MM | D36: 5615-01 | E36: 80
A37: 46091 | B37: 030623-0001-02 | C37: RÓTULO DE IDENTIF BLACK 21L 450X250MM | D37: 5615-02 | E37: 229
A38: 46091 | B38: 030623-0002-02 | C38: RÓTULO DE IDENTIF WHITE 21L | D38: 5616-01 | E38: 87
A39: 46091 | B39: 030623-0002-02 | C39: RÓTULO DE IDENTIF WHITE 21L | D39: 5616-02 | E39: 513
A40: 46091 | B40: 030623-0004-01 | C40: RÓTULO DE IDENTIF WHITE 34L 530X285MM | D40: 5617-01 | E40: 44
A41: 46091 | B41: 030623-0004-01 | C41: RÓTULO DE IDENTIF WHITE 34L 530X285MM | D41: 5617-02 | E41: 49
A42: 46091 | B42: 030623-0005-01 | C42: RÓTULO DE IDENTIF BLACK 34L 530X285MM | D42: 5774-01 | E42: 34
A43: 46091 | B43: 030623-0005-01 | C43: RÓTULO DE IDENTIF BLACK 34L 530X285MM | D43: 5774-02 | E43: 148
A44: 46091 | B44: 030623-0006-01 | C44: RÓTULO DE IDENTIF BLACK 21L 450X250MM | D44: 5615-03 | E44: 457
A45: 46091 | B45: 030623-0006-01 | C45: RÓTULO DE IDENTIF BLACK 21L 450X250MM | D45: 5615-04 | E45: 98
A46: 46091 | B46: 030623-0007-01 | C46: RÓTULO DE IDENTIF WHITE 21L 450X250MM | D46: 5616-03 | E46: 232
A47: 46091 | B47: 030623-0007-01 | C47: RÓTULO DE IDENTIF WHITE 21L 450X250MM | D47: 5616-04 | E47: 22
... A53: 46091 | B53: 030623-0010-01 | C53: RÓTULO DE IDENTIF MIRROR 21L 450X250MM | D53: 5619-02 | E53: 72
A54: 10/03/2026 Total | E54: 3432
A55: 46100 | B55: 030623-0002-02 | C55: RÓTULO DE IDENTIF WHITE 21L | D55: 5616-02 | E55: 173
A56: 46100 | B56: 030623-0005-01 | C56: RÓTULO DE IDENTIF BLACK 34L 530X285MM | D56: 5774-01 | E56: 9
A57: 46100 | B57: 030623-0005-01 | C57: RÓTULO DE IDENTIF BLACK 34L 530X285MM | D57: 5774-02 | E57: 2
A58: 46100 | B58: 030623-0006-01 | C58: RÓTULO DE IDENTIF BLACK 21L 450X250MM | D58: 5615-03 | E58: 47
A59: 46100 | B59: 030623-0006-01 | C59: RÓTULO DE IDENTIF BLACK 21L 450X250MM | D59: 5615-04 | E59: 148
A60: 46100 | B60: 030623-0007-01 | C60: RÓTULO DE IDENTIF WHITE 21L 450X250MM | D60: 5616-03 | E60: 6
...

Sheet SOLICITACOES 
A1: SOLICITAÇÃO | B1: DATA SOLICITAÇÃO | C1: SOLICITANTE | D1: DESTINO | E1: CODIGO DA EMBALAGEM | F1: DESCRIÇAO DA EMBALAGEM | G1: TIPO | H1: TIPO DE EMBALAGEM | I1: CODIGO DO PRODUTO | J1: MODELO DO PRODUTO | K1: MODELO | L1: SOLICITADO | M1: ENVIADO | N1: PENDENTE | O1: ENTREGA (COMPRAS) | P1: ENVIO (EXPEDIÇÃO) | Q1: STATUS | R1: Comentário | S1: NF | T1: PLACA | U1: PREVISÃO DE ENTREGA
A2: 1 | B2: 46065 | C2: VANESSA | D2: BAHIA | E2: 040117-0002-02 | F2: CX DE EMBALAGEM INDIVIDUAL AWS-BBS-01-B | G2: EMBALAGEM | H2: CAIXA INDIVIDUAL | I2: 4899-01 | J2: =VLOOKUP(I2,'DESCRICAO PRODUTO'!$A:$C,2,0) -> BOOMBOX AWS-BBS-01-B BIVOLT | K2: =VLOOKUP(I2,'DESCRICAO PRODUTO'!$A:$C,3,0) -> BBS PRETO | L2: 1540 | M2: 1540 | N2: =M2-L2 -> 0 | O2: 46100 | P2: 46108 | Q2: FINALIZADO | S2: 29858 | T2: JXA2303 | U2: 46128
A3: 1 | B3: 46065 | C3: VANESSA | D3: BAHIA | E3: 040117-0004-01 | F3: CX DE EMBALAGEM INDIVIDUAL AWS-BBS-01-BG | G3: EMBALAGEM | H3: CAIXA INDIVIDUAL | I3: 5782-01 | J3: =VLOOKUP(I3,'DESCRICAO PRODUTO'!$A:$C,2,0) -> BOOMBOX AWS-BBS-01-BG BIVOLT | K3: =VLOOKUP(I3,'DESCRICAO PRODUTO'!$A:$C,3,0) -> BBS BG | L3: 57 | M3: 57 | N3: =M3-L3 -> 0 | O3: 46100 | P3: 46108 | Q3: FINALIZADO | S3: 29860 | T3: JXA2303 | U3: 46128
A4: 1 | B4: 46065 | C4: VANESSA | D4: BAHIA | E4: 040117-0003-01 | F4: CX DE EMBALAGEM INDIVIDUAL AWS-BBS-01-GR | G4: EMBALAGEM | H4: CAIXA INDIVIDUAL | I4: 4487-01 | J4: =VLOOKUP(I4,'DESCRICAO PRODUTO'!$A:$C,2,0) -> BOOMBOX AWS-BBS-01-GR BIVOLT | K4: =VLOOKUP(I4,'DESCRICAO PRODUTO'!$A:$C,3,0) -> BBS GR | L4: 5 | M4: 5 | N4: =M4-L4 -> 0 | O4: 46100 | P4: 46107 | Q4: FINALIZADO | S4: 29833 | T4: MNK6A35 | U4: 46127
A5: 1 | B5: 46065 | C5: VANESSA | D5: BAHIA | E5: 040117-0001-01 | F5: CX DE EMBALAGEM INDIVIDUAL BX-18 | G5: EMBALAGEM | H5: CAIXA INDIVIDUAL | I5: 5141-04 | J5: =VLOOKUP(I5,'DESCRICAO PRODUTO'!$A:$C,2,0) -> BOOMBOX BX-18 BIVOLT UP ORANGE | K5: =VLOOKUP(I5,'DESCRICAO PRODUTO'!$A:$C,3,0) -> BX 18 | L5: 38 | N5: =M5-L5 -> -38 | O5: TBC | P5: TBC | Q5: INATIVO
A6: 1 | B6: 46065 | C6: VANESSA | D6: BAHIA | E6: 2017-71 | F6: CAIXA EMBALAGEM COLETIVA BX-18 | G6: EMBALAGEM | H6: CAIXA COLETIVA | I6: 5141-04 | J6: =VLOOKUP(I6,'DESCRICAO PRODUTO'!$A:$C,2,0) -> BOOMBOX BX-18 BIVOLT UP ORANGE | K6: =VLOOKUP(I6,'DESCRICAO PRODUTO'!$A:$C,3,0) -> BX 18 | L6: 10 | N6: =M6-L6 -> -10 | O6: TBC | P6: TBC | Q6: INATIVO
A7: 1 | B7: 46065 | C7: VANESSA | D7: BAHIA | E7: 040117-0001-01 | F7: CX DE EMBALAGEM INDIVIDUAL BX-18 | G7: EMBALAGEM | H7: CAIXA INDIVIDUAL | I7: 5141-02 | J7: =VLOOKUP(I7,'DESCRICAO PRODUTO'!$A:$C,2,0) -> BOOMBOX BX-18 BIVOLT UP ORANGE | K7: =VLOOKUP(I7,'DESCRICAO PRODUTO'!$A:$C,3,0) -> BX 18 | L7: 4 | N7: =M7-L7 -> -4 | O7: TBC | P7: TBC | Q7: INATIVO
A8: 1 | B8: 46065 | C8: VANESSA | D8: BAHIA | E8: 2017-71 | F8: CAIXA EMBALAGEM COLETIVA BX-18 | G8: EMBALAGEM | H8: CAIXA COLETIVA | I8: 5141-02 | J8: =VLOOKUP(I8,'DESCRICAO PRODUTO'!$A:$C,2,0) -> BOOMBOX BX-18 BIVOLT UP ORANGE | K8: =VLOOKUP(I8,'DESCRICAO PRODUTO'!$A:$C,3,0) -> BX 18 | L8: 1 | N8: =M8-L8 -> -1 | O8: TBC | P8: TBC | Q8: INATIVO
A9: 1 | B9: 46065 | C9: VANESSA | D9: BAHIA | E9: 2017-71 | F9: CAIXA EMBALAGEM COLETIVA BX-18 | G9: EMBALAGEM | H9: CAIXA COLETIVA | I9: 5141-03 | J9: =VLOOKUP(I9,'DESCRICAO PRODUTO'!$A:$C,2,0) -> BOOMBOX BX-18 BIVOLT UP ORANGE | K9: =VLOOKUP(I9,'DESCRICAO PRODUTO'!$A:$C,3,0) -> BX 18 | L9: 5 | N9: =M9-L9 -> -5 | O9: TBC | P9: TBC | Q9: INATIVO
A10: 1 | B10: 46065 | C10: VANESSA | D10: BAHIA | E10: 2016-12 | F10: EMBALAGEM INDIVIDUAL BX-19 | G10: EMBALAGEM | H10: CAIXA INDIVIDUAL | I10: 5241-01 | J10: =VLOOKUP(I10,'DESCRICAO PRODUTO'!$A:$C,2,0) -> BOOMBOX BX-19 BIVOLT UP DYNAMIC | K10: =VLOOKUP(I10,'DESCRICAO PRODUTO'!$A:$C,3,0) -> BX 19 | L10: 10 | N10: =M10-L10 -> -10 | O10: TBC | P10: TBC | Q10: INATIVO
A11: 1 | B11: 46065 | C11: VANESSA | D11: BAHIA | E11: 2017-71 | F11: CAIXA EMBALAGEM COLETIVA BX-18 | G11: EMBALAGEM | H11: CAIXA COLETIVA | I11: 5241-01 | J11: =VLOOKUP(I11,'DESCRICAO PRODUTO'!$A:$C,2,0) -> BOOMBOX BX-19 BIVOLT UP DYNAMIC | K11: =VLOOKUP(I11,'DESCRICAO PRODUTO'!$A:$C,3,0) -> BX 19 | L11: 3 | N11: =M11-L11 -> -3 | O11: TBC | P11: TBC | Q11: INATIVO
A12: 1 | B12: 46065 | C12: VANESSA | D12: BAHIA | E12: 2016-12 | F12: EMBALAGEM INDIVIDUAL BX-19 | G12: EMBALAGEM | H12: CAIXA INDIVIDUAL | I12: 5241-02 | J12: =VLOOKUP(I12,'DESCRICAO PRODUTO'!$A:$C,2,0) -> BOOMBOX BX-19 BIVOLT UP DYNAMIC | K12: =VLOOKUP(I12,'DESCRICAO PRODUTO'!$A:$C,3,0) -> BX 19 | L12: 2 | N12: =M12-L12 -> -2 | O12: TBC | P12: TBC | Q12: INATIVO
A13: 1 | B13: 46065 | C13: VANESSA | D13: BAHIA | E13: 2017-71 | F13: CAIXA EMBALAGEM COLETIVA BX-18 | G13: EMBALAGEM | H13: CAIXA COLETIVA | I13: 5241-02 | J13: =VLOOKUP(I13,'DESCRICAO PRODUTO'!$A:$C,2,0) -> BOOMBOX BX-19 BIVOLT UP DYNAMIC | K13: =VLOOKUP(I13,'DESCRICAO PRODUTO'!$A:$C,3,0) -> BX 19 | L13: 2 | N13: =M13-L13 -> -2 | O13: TBC | P13: TBC | Q13: INATIVO
A14: 1 | B14: 46065 | C14: VANESSA | D14: BAHIA | E14: 2017-96 | F14: EMBALAGEM INDIVIDUAL BX-21 NV | G14: EMBALAGEM | H14: CAIXA INDIVIDUAL | I14: 5243-02 | J14: =VLOOKUP(I14,'DESCRICAO PRODUTO'!$A:$C,2,0) -> BOOMBOX BX-21ML BIVOLT . | K14: =VLOOKUP(I14,'DESCRICAO PRODUTO'!$A:$C,3,0) -> BX 21 | L14: 73 | N14: =M14-L14 -> -73 | O14: TBC | P14: TBC | Q14: INATIVO
A15: 1 | B15: 46065 | C15: VANESSA | D15: BAHIA | E15: 2017-71 | F15: CAIXA EMBALAGEM COLETIVA BX-18 | G15: EMBALAGEM | H15: CAIXA COLETIVA | I15: 5243-02 | J15: =VLOOKUP(I15,'DESCRICAO PRODUTO'!$A:$C,2,0) -> BOOMBOX BX-21ML BIVOLT . | K15: =VLOOKUP(I15,'DESCRICAO PRODUTO'!$A:$C,3,0) -> BX 21 | L15: 21 | N15: =M15-L15 -> -21 | O15: TBC | P15: TBC | Q15: INATIVO
A16: 1 | B16: 46065 | C16: VANESSA | D16: BAHIA | E16: 2017-96 | F16: EMBALAGEM INDIVIDUAL BX-21 NV | G16: EMBALAGEM | H16: CAIXA INDIVIDUAL | I16: 5243-01 | J16: =VLOOKUP(I16,'DESCRICAO PRODUTO'!$A:$C,2,0) -> BOOMBOX BX-21ML BIVOLT . | K16: =VLOOKUP(I16,'DESCRICAO PRODUTO'!$A:$C,3,0) -> BX 21 | L16: 37 | N16: =M16-L16 -> -37 | O16: TBC | P16: TBC | Q16: INATIVO
A17: 1 | B17: 46065 | C17: VANESSA | D17: BAHIA | E17: 2017-71 | F17: CAIXA EMBALAGEM COLETIVA BX-18 | G17: EMBALAGEM | H17: CAIXA COLETIVA | I17: 5243-01 | J17: =VLOOKUP(I17,'DESCRICAO PRODUTO'!$A:$C,2,0) -> BOOMBOX BX-21ML BIVOLT . | K17: =VLOOKUP(I17,'DESCRICAO PRODUTO'!$A:$C,3,0) -> BX 21 | L17: 10 | N17: =M17-L17 -> -10 | O17: TBC | P17: TBC | Q17: INATIVO
A18: 1 | B18: 46065 | C18: VANESSA | D18: BAHIA | E18: 040117-0005-01 | F18: CX DE EMBALAGEM INDIVIDUAL AWS-BBS-01-LB | G18: EMBALAGEM | H18: CAIXA INDIVIDUAL | I18: 9531-01 | J18: =VLOOKUP(I18,'DESCRICAO PRODUTO'!$A:$C,2,0) -> BOOMBOX C/ LUZES AWS-BBS-01-LBL BIVOLT | K18: =VLOOKUP(I18,'DESCRICAO PRODUTO'!$A:$C,3,0) -> BBS LBL | L18: 118 | M18: 118 | N18: =M18-L18 -> 0 | O18: 46100 | P18: 46107 | Q18: FINALIZADO | S18: 29833 | T18: MNK6A35 | U18: 46127
A19: 1 | B19: 46065 | C19: VANESSA | D19: BAHIA | E19: 2016-78 | F19: EMBALAGEM IND NBX-13 - REV.01 | G19: EMBALAGEM | H19: CAIXA INDIVIDUAL | I19: 5161-01 | J19: =VLOOKUP(I19,'DESCRICAO PRODUTO'!$A:$C,2,0) -> BOOMBOX NBX-13 BIVOLT UP BLACK | K19: =VLOOKUP(I19,'DESCRICAO PRODUTO'!$A:$C,3,0) -> BX 13 | L19: 172 | N19: =M19-L19 -> -172 | O19: TBC | P19: TBC | Q19: INATIVO
A20: 1 | B20: 46065 | C20: VANESSA | D20: BAHIA | E20: 2016-78 | F20: EMBALAGEM IND NBX-13 - REV.01 | G20: EMBALAGEM | H20: CAIXA INDIVIDUAL | I20: 5161-01 | J20: =VLOOKUP(I20,'DESCRICAO PRODUTO'!$A:$C,2,0) -> BOOMBOX NBX-13 BIVOLT UP BLACK | K20: =VLOOKUP(I20,'DESCRICAO PRODUTO'!$A:$C,3,0) -> BX 13 | L20: 46 | N20: =M20-L20 -> -46 | O20: TBC | P20: TBC | Q20: INATIVO
A21: 1 | B21: 46065 | C21: VANESSA | D21: BAHIA | E21: 2016-78 | F21: EMBALAGEM IND NBX-13 - REV.01 | G21: EMBALAGEM | H21: CAIXA INDIVIDUAL | I21: 5161-02 | J21: =VLOOKUP(I21,'DESCRICAO PRODUTO'!$A:$C,2,0) -> BOOMBOX NBX-13 BIVOLT UP BLACK | K21: =VLOOKUP(I21,'DESCRICAO PRODUTO'!$A:$C,3,0) -> BX 13 | L21: 36 | N21: =M21-L21 -> -36 | O21: TBC | P21: TBC | Q21: INATIVO
A22: 1 | B22: 46065 | C22: VANESSA | D22: BAHIA | E22: 2017-71 | F22: CAIXA EMBALAGEM COLETIVA BX-18 | G22: EMBALAGEM | H22: CAIXA COLETIVA | I22: 5161-02 | J22: =VLOOKUP(I22,'DESCRICAO PRODUTO'!$A:$C,2,0) -> BOOMBOX NBX-13 BIVOLT UP BLACK | K22: =VLOOKUP(I22,'DESCRICAO PRODUTO'!$A:$C,3,0) -> BX 13 | L22: 12 | N22: =M22-L22 -> -12 | O22: TBC | P22: TBC | Q22: INATIVO
A23: 1 | B23: 46065 | C23: VANESSA | D23: BAHIA | E23: 2019-23 | F23: EMBALAGEM INDIVIDUAL CM-13 | G23: EMBALAGEM | H23: CAIXA INDIVIDUAL | I23: 8323-03 | J23: =VLOOKUP(I23,'DESCRICAO PRODUTO'!$A:$C,2,0) -> CAIXA AMPLIFICADA CM-13 BIVOLT . | K23: =VLOOKUP(I23,'DESCRICAO PRODUTO'!$A:$C,3,0) -> CM 13 | L23: 1 | N23: =M23-L23 -> -1 | O23: TBC | P23: TBC | Q23: INATIVO
A24: 1 | B24: 46065 | C24: VANESSA | D24: BAHIA | E24: 2019-75 | F24: CAIXA DE EMBALAGEM INDIVIDUAL CM-14 | G24: EMBALAGEM | H24: CAIXA INDIVIDUAL | I24: 6840-02 | J24: =VLOOKUP(I24,'DESCRICAO PRODUTO'!$A:$C,2,0) -> CAIXA AMPLIFICADA CM-14 BIVOLT . | K24: =VLOOKUP(I24,'DESCRICAO PRODUTO'!$A:$C,3,0) -> CM 14 | L24: 1 | N24: =M24-L24 -> -1 | O24: TBC | P24: TBC | Q24: INATIVO
A25: 1 | B25: 46065 | C25: VANESSA | D25: BAHIA | E25: 040225-0002-02 | F25: CX DE EMBALAGEM COLETIVA CM-150/CM-220-N | G25: EMBALAGEM | H25: CAIXA COLETIVA | I25: 5487-01 | J25: =VLOOKUP(I25,'DESCRICAO PRODUTO'!$A:$C,2,0) -> CAIXA AMPLIFICADA CM-150 BIVOLT . | K25: =VLOOKUP(I25,'DESCRICAO PRODUTO'!$A:$C,3,0) -> CM150 | L25: 200 | N25: =M25-L25 -> -200 | Q25: PENDENTE | R25: Solicitar compra por e-mail
A26: 1 | B26: 46065 | C26: VANESSA | D26: BAHIA | E26: 040125-0018-01 | F26: CX DE EMBALAGEM INDIVIDUAL CM-150 | G26: EMBALAGEM | H26: CAIXA INDIVIDUAL | I26: 5487-02 | J26: =VLOOKUP(I26,'DESCRICAO PRODUTO'!$A:$C,2,0) -> CAIXA AMPLIFICADA CM-150 BIVOLT . | K26: =VLOOKUP(I26,'DESCRICAO PRODUTO'!$A:$C,3,0) -> CM150 | L26: 580 | M26: 580 | N26: =M26-L26 -> 0 | O26: 46153 | P26: 46160 | Q26: FINALIZADO | S26: 30305 | T26: JXU2478 | U26: 46184
A27: 1 | B27: 46065 | C27: VANESSA | D27: BAHIA | E27: 040225-0002-02 | F27: CX DE EMBALAGEM COLETIVA CM-150/CM-220-N | G27: EMBALAGEM | H27: CAIXA COLETIVA | I27: 5487-02 | J27: =VLOOKUP(I27,'DESCRICAO PRODUTO'!$A:$C,2,0) -> CAIXA AMPLIFICADA CM-150 BIVOLT . | K27: =VLOOKUP(I27,'DESCRICAO PRODUTO'!$A:$C,3,0) -> CM150 | L27: 406 | N27: =M27-L27 -> -406 | Q27: PENDENTE | R27: Solicitar compra por e-mail
A28: 1 | B28: 46065 | C28: VANESSA | D28: BAHIA | E28: 2019-77 | F28: CAIXA EMBALAGEM INDIVIDUAL CM-16 | G28: EMBALAGEM | H28: CAIXA INDIVIDUAL | I28: 5595-01 | J28: =VLOOKUP(I28,'DESCRICAO PRODUTO'!$A:$C,2,0) -> CAIXA AMPLIFICADA CM-16 BIVOLT . | K28: =VLOOKUP(I28,'DESCRICAO PRODUTO'!$A:$C,3,0) -> CM 16 | L28: 1 | N28: =M28-L28 -> -1 | O28: TBC | P28: TBC | Q28: INATIVO
A29: 1 | B29: 46065 | C29: VANESSA | D29: BAHIA | E29: 040125-0002-02 | F29: CX DE EMBALAGEM INDIVIDUAL CM-250 | G29: EMBALAGEM | H29: CAIXA INDIVIDUAL | I29: 2108-01 | J29: =VLOOKUP(I29,'DESCRICAO PRODUTO'!$A:$C,2,0) -> CAIXA AMPLIFICADA CM-250 BIVOLT . | K29: =VLOOKUP(I29,'DESCRICAO PRODUTO'!$A:$C,3,0) -> CM 250 | L29: 108 | M29: 108 | N29: =M29-L29 -> 0 | O29: 46153 | P29: 46168 | Q29: FINALIZADO | S29: 30384 | T29: JXB1402 | U29: 46189
A30: 1 | B30: 46065 | C30: VANESSA | D30: BAHIA | E30: 040225-0003-01 | F30: CX DE EMBALAGEM COLETIVA CM-250 | G30: EMBALAGEM | H30: CAIXA COLETIVA | I30: 2108-01 | J30: =VLOOKUP(I30,'DESCRICAO PRODUTO'!$A:$C,2,0) -> CAIXA AMPLIFICADA CM-250 BIVOLT . | K30: =VLOOKUP(I30,'DESCRICAO PRODUTO'!$A:$C,3,0) -> CM 250 | L30: 30 | M30: 30 | N30: =M30-L30 -> 0 | O30: 46100 | P30: 46122 | Q30: FINALIZADO | S30: 29913 | T30: JXA5313 | U30: 46146
A31: 1 | B31: 46065 | C31: VANESSA | D31: BAHIA | E31: 040125-0002-02 | F31: CX DE EMBALAGEM INDIVIDUAL CM-250 | G31: EMBALAGEM | H31: CAIXA INDIVIDUAL | I31: 2108-02 | J31: =VLOOKUP(I31,'DESCRICAO PRODUTO'!$A:$C,2,0) -> CAIXA AMPLIFICADA CM-250 BIVOLT . | K31: =VLOOKUP(I31,'DESCRICAO PRODUTO'!$A:$C,3,0) -> CM 250 | L31: 19 | M31: 19 | N31: =M31-L31 -> 0 | O31: 46153 | P31: 46168 | Q31: FINALIZADO | S31: 30384 | T31: JXB1402 | U31: 46189
A32: 1 | B32: 46065 | C32: VANESSA | D32: BAHIA | E32: 040225-0003-01 | F32: CX DE EMBALAGEM COLETIVA CM-250 | G32: EMBALAGEM | H32: CAIXA COLETIVA | I32: 2108-02 | J32: =VLOOKUP(I32,'DESCRICAO PRODUTO'!$A:$C,2,0) -> CAIXA AMPLIFICADA CM-250 BIVOLT . | K32: =VLOOKUP(I32,'DESCRICAO PRODUTO'!$A:$C,3,0) -> CM 250 | L32: 8 | M32: 8 | N32: =M32-L32 -> 0 | O32: 46100 | P32: 46122 | Q32: FINALIZADO | S32: 29913 | T32: JXA5313 | U32: 46146
A33: 1 | B33: 46065 | C33: VANESSA | D33: BAHIA | E33: 040225-0003-01 | F33: CX DE EMBALAGEM COLETIVA CM-250 | G33: EMBALAGEM | H33: CAIXA COLETIVA | I33: 2108-03 | J33: =VLOOKUP(I33,'DESCRICAO PRODUTO'!$A:$C,2,0) -> CAIXA AMPLIFICADA CM-250 BIVOLT . | K33: =VLOOKUP(I33,'DESCRICAO PRODUTO'!$A:$C,3,0) -> CM 250 | L33: 236 | M33: 236 | N33: =M33-L33 -> 0 | O33: 46100 | P33: 46122 | Q33: FINALIZADO | S33: 29913 | T33: JXA5313 | U33: 46146
A34: 1 | B34: 46065 | C34: VANESSA | D34: BAHIA | E34: 040125-0012-01 | F34: CX DE EMBALAGEM INDIVIDUAL CM-400 | G34: EMBALAGEM | H34: CAIXA INDIVIDUAL | I34: 0685-04 | J34: =VLOOKUP(I34,'DESCRICAO PRODUTO'!$A:$C,2,0) -> CAIXA AMPLIFICADA CM-400 BIVOLT . | K34: CM400 | L34: 2360 | M34: 2360 | N34: =M34-L34 -> 0 | O34: 46139 | P34: 46107 | Q34: FINALIZADO | S34: 29832 | T34: MNK6A35 | U34: 46127
A35: 1 | B35: 46065 | C35: VANESSA | D35: BAHIA | E35: 040125-0012-01 | F35: CX DE EMBALAGEM INDIVIDUAL CM-400 | G35: EMBALAGEM | H35: CAIXA INDIVIDUAL | I35: 0685-03 | J35: =VLOOKUP(I35,'DESCRICAO PRODUTO'!$A:$C,2,0) -> CAIXA AMPLIFICADA CM-400 BIVOLT . | K35: CM400 | L35: 485 | M35: 485 | N35: =M35-L35 -> 0 | O35: 46139 | P35: 46107 | Q35: FINALIZADO | S35: 29832 | T35: MNK6A35 | U35: 46127
A36: 1 | B36: 46065 | C36: VANESSA | D36: BAHIA | E36: 2016-52 | F36: EMBALAGEM INDIVIDUAL CM-400 AMPLA | G36: EMBALAGEM | H36: CAIXA INDIVIDUAL | I36: 0685-01 | J36: =VLOOKUP(I36,'DESCRICAO PRODUTO'!$A:$C,2,0) -> CAIXA AMPLIFICADA CM-400 BIVOLT . | K36: CM400 | L36: 34 | M36: 34 | N36: =M36-L36 -> 0 | O36: 46153 | P36: 46168 | Q36: FINALIZADO | S36: 30384 | T36: JXB1402 | U36: 46189
A37: 1 | B37: 46065 | C37: VANESSA | D37: BAHIA | E37: 040125-0010-01 | F37: CX DE EMBALAGEM INDIVIDUAL CM-400 | G37: EMBALAGEM | H37: CAIXA INDIVIDUAL | I37: 0685-02 | J37: =VLOOKUP(I37,'DESCRICAO PRODUTO'!$A:$C,2,0) -> CAIXA AMPLIFICADA CM-400 BIVOLT . | K37: CM400 | L37: 185 | M37: 185 | N37: =M37-L37 -> 0 | O37: 46153 | P37: 46168 | Q37: FINALIZADO | S37: 30384 | T37: JXB1402 | U37: 46189
A38: 1 | B38: 46065 | C38: VANESSA | D38: BAHIA | E38: 2016-52 | F38: EMBALAGEM INDIVIDUAL CM-400 AMPLA | G38: EMBALAGEM | H38: CAIXA INDIVIDUAL | I38: 0685-01 | J38: =VLOOKUP(I38,'DESCRICAO PRODUTO'!$A:$C,2,0) -> CAIXA AMPLIFICADA CM-400 BIVOLT . | K38: CM400 | L38: 170 | M38: 170 | N38: =M38-L38 -> 0 | O38: 46153 | P38: 46168 | Q38: FINALIZADO | S38: 30384 | T38: JXB1402 | U38: 46189
A39: 1 | B39: 46065 | C39: VANESSA | D39: BAHIA | E39: 2017-22 | F39: EMBALAGEM IND PARDA CM500 - ONDA BC | G39: EMBALAGEM | H39: CAIXA INDIVIDUAL | I39: 1705-02 | J39: =VLOOKUP(I39,'DESCRICAO PRODUTO'!$A:$C,2,0) -> CAIXA AMPLIFICADA CM-500 BIVOLT . | K39: =VLOOKUP(I39,'DESCRICAO PRODUTO'!$A:$C,3,0) -> CM 500 | L39: 15 | N39: =M39-L39 -> -15 | O39: TBC | P39: TBC | Q39: INATIVO
A40: 1 | B40: 46065 | C40: VANESSA | D40: BAHIA | E40: 2017-18 | F40: EMBALAGEM INDIVIDUAL CM-500 ONDA B | G40: EMBALAGEM | H40: CAIXA INDIVIDUAL | I40: 1705-01 | J40: =VLOOKUP(I40,'DESCRICAO PRODUTO'!$A:$C,2,0) -> CAIXA AMPLIFICADA CM-500 BIVOLT. | K40: =VLOOKUP(I40,'DESCRICAO PRODUTO'!$A:$C,3,0) -> CM 500 | L40: 22 | N40: =M40-L40 -> -22 | O40: TBC | P40: TBC | Q40: INATIVO
...

Sheet PALETIZACAO
A1: CODIGO DA EMBALAGEM | B1: DESCRIÇAO DA EMBALAGEM | C1: PALETIZAÇAO PADRAO ALMOXARIFADO | D1: TIPO | E1: TIPO DE EMBALAGEM | F1: CODIGO DO PRODUTO | G1: MODELO DO PRODUTO | H1: MODELO
A2: 040117-0005-01 | B2: CX DE EMBALAGEM INDIVIDUAL AWS-BBS-01-LB | C2: 300 | D2: EMBALAGEM | E2: CAIXA INDIVIDUAL | F2: 9531-01 | G2: =VLOOKUP(F2,'[1]DESCRICAO PRODUTO'!$A:$C,2,0) -> BOOMBOX C/ LUZES AWS-BBS-01-LBL BIVOLT | H2: =VLOOKUP(F2,'[1]DESCRICAO PRODUTO'!$A:$C,3,0) -> BBS LBL
A3: 040117-0002-01 | B3: CX DE EMBALAGEM INDIVIDUAL AWS-BBS-01-B | C3: 300 | D3: EMBALAGEM | E3: CAIXA INDIVIDUAL | F3: 4899-01 | G3: =VLOOKUP(F3,'[1]DESCRICAO PRODUTO'!$A:$C,2,0) -> BOOMBOX AWS-BBS-01-B BIVOLT | H3: =VLOOKUP(F3,'[1]DESCRICAO PRODUTO'!$A:$C,3,0) -> BBS PRETO
A4: 040125-0037-01 | B4: CX DE EMBALAGEM INDIVIDUAL CM-220-N | C4: 300 | D4: EMBALAGEM | E4: CAIXA INDIVIDUAL | F4: 7040-01 | G4: =VLOOKUP(F4,'[1]DESCRICAO PRODUTO'!$A:$C,2,0) -> CAIXA AMPLIFICADA CM-220-N BIV. | H4: =VLOOKUP(F4,'[1]DESCRICAO PRODUTO'!$A:$C,3,0) -> CM 220 N
A5: 040225-0003-01 | B5: CX DE EMBALAGEM COLETIVA CM-250 | C5: 180 | D5: EMBALAGEM | E5: CAIXA COLETIVA | F5: 2108-02 | G5: =VLOOKUP(F5,'[1]DESCRICAO PRODUTO'!$A:$C,2,0) -> CAIXA AMPLIFICADA CM-250 BIVOLT . | H5: =VLOOKUP(F5,'[1]DESCRICAO PRODUTO'!$A:$C,3,0) -> CM 250
A6: 040125-0007-01 | B6: CX DE EMBALAGEM INDIVIDUAL CM-250 | C6: 300 | D6: EMBALAGEM | E6: CAIXA INDIVIDUAL | F6: 2108-03 | G6: =VLOOKUP(F6,'[1]DESCRICAO PRODUTO'!$A:$C,2,0) -> CAIXA AMPLIFICADA CM-250 BIVOLT . | H6: =VLOOKUP(F6,'[1]DESCRICAO PRODUTO'!$A:$C,3,0) -> CM 250
A7: 040125-0029-01 | B7: CX DE EMBALAGEM INDIVIDUAL CM-400-L | C7: 300 | D7: EMBALAGEM | E7: CAIXA INDIVIDUAL | F7: 8998-01 | G7: =VLOOKUP(F7,'[1]DESCRICAO PRODUTO'!$A:$C,2,0) -> CAIXA AMPLIFICADA CM-400-L BIVOLT . | H7: =VLOOKUP(F7,'[1]DESCRICAO PRODUTO'!$A:$C,3,0) -> CM 400L
A8: 040125-0014-01 | B8: CX DE EMBALAGEM INDIVIDUAL CM-550 | C8: 150 | D8: EMBALAGEM | E8: CAIXA INDIVIDUAL | F8: 2555-05 | G8: =VLOOKUP(F8,'[1]DESCRICAO PRODUTO'!$A:$C,2,0) -> CAIXA AMPLIFICADA CM-550 BIVOLT . | H8: =VLOOKUP(F8,'[1]DESCRICAO PRODUTO'!$A:$C,3,0) -> CM 550
A9: 040125-0030-01 | B9: CX DE EMBALAGEM INDIVIDUAL CM-550-L | C9: 150 | D9: EMBALAGEM | E9: CAIXA INDIVIDUAL | F9: 8999-01 | G9: =VLOOKUP(F9,'[1]DESCRICAO PRODUTO'!$A:$C,2,0) -> CAIXA AMPLIFICADA CM-550-L BIVOLT . | H9: =VLOOKUP(F9,'[1]DESCRICAO PRODUTO'!$A:$C,3,0) -> CM 550L
A10: 040125-0009-01 | B10: CX DE EMBALAGEM INDIVIDUAL CM-700 | C10: 160 | D10: EMBALAGEM | E10: CAIXA INDIVIDUAL | F10: 9915-01 | G10: =VLOOKUP(F10,'[1]DESCRICAO PRODUTO'!$A:$C,2,0) -> CAIXA AMPLIFICADA CM-700 BIVOLT . | H10: =VLOOKUP(F10,'[1]DESCRICAO PRODUTO'!$A:$C,3,0) -> CM 700
A11: 040125-0041-02 | B11: CX DE EMBALAGEM INDIVIDUAL CM-1000-N | C11: 160 | D11: EMBALAGEM | E11: CAIXA INDIVIDUAL | F11: 7045-01 | G11: =VLOOKUP(F11,'[1]DESCRICAO PRODUTO'!$A:$C,2,0) -> CAIXA AMPLIFICADA CM-1000-N BIV. | H11: =VLOOKUP(F11,'[1]DESCRICAO PRODUTO'!$A:$C,3,0) -> CM1000N
A12: 040225-0002-02 | B12: CX DE EMBALAGEM COLETIVA CM-150 | C12: 160 | D12: EMBALAGEM | E12: CAIXA COLETIVA | F12: 5487-01 | G12: =VLOOKUP(F12,'[1]DESCRICAO PRODUTO'!$A:$C,2,0) -> CAIXA AMPLIFICADA CM-150 BIVOLT . | H12: =VLOOKUP(F12,'[1]DESCRICAO PRODUTO'!$A:$C,3,0) -> CM150
A13: 040125-0018-01 | B13: CX DE EMBALAGEM INDIVIDUAL CM-150 | C13: 300 | D13: EMBALAGEM | E13: CAIXA INDIVIDUAL | F13: 5487-01 | G13: =VLOOKUP(F13,'[1]DESCRICAO PRODUTO'!$A:$C,2,0) -> CAIXA AMPLIFICADA CM-150 BIVOLT . | H13: =VLOOKUP(F13,'[1]DESCRICAO PRODUTO'!$A:$C,3,0) -> CM150
... A15: 040225-0004-01 | B15: CX DE EMBALAGEM COLETIVA CM-400-L | C15: 40 | D15: EMBALAGEM | E15: CAIXA COLETIVA | F15: 7041-01 | G15: =VLOOKUP(F15,'[1]DESCRICAO PRODUTO'!$A:$C,2,0) -> CAIXA AMPLIFICADA CM-300-N BIV. | H15: =VLOOKUP(F15,'[1]DESCRICAO PRODUTO'!$A:$C,3,0) -> CM300N
A16: 040125-0010-01 | B16: CX DE EMBALAGEM INDIVIDUAL CM-400 | C16: 150 | D16: EMBALAGEM | E16: CAIXA INDIVIDUAL | F16: 0685-02 | G16: =VLOOKUP(F16,'[1]DESCRICAO PRODUTO'!$A:$C,2,0) -> CAIXA AMPLIFICADA CM-400 BIVOLT . | H16: CM400
A17: 040125-0012-01 | B17: CX DE EMBALAGEM INDIVIDUAL CM-400 | C17: 150 | D17: EMBALAGEM | E17: CAIXA INDIVIDUAL | F17: 0685-03 | G17: =VLOOKUP(F17,'[1]DESCRICAO PRODUTO'!$A:$C,2,0) -> CAIXA AMPLIFICADA CM-400 BIVOLT . | H17: CM400
A18: 040125-0040-01 | B18: CX DE EMBALAGEM INDIVIDUAL CM-650-N | C18: 150 | D18: EMBALAGEM | E18: CAIXA INDIVIDUAL | F18: 7044-01 | G18: =VLOOKUP(F18,'[1]DESCRICAO PRODUTO'!$A:$C,2,0) -> CAIXA AMPLIFICADA CM-650-N BIV. | H18: =VLOOKUP(F18,'[1]DESCRICAO PRODUTO'!$A:$C,3,0) -> CM650N
A19: 040125-0023-01 | B19: CX DE EMBALAGEM INDIVIDUAL T1W | C19: 100 | D19: EMBALAGEM | E19: CAIXA INDIVIDUAL | F19: 5116-01 | G19: =VLOOKUP(F19,'[1]DESCRICAO PRODUTO'!$A:$C,2,0) -> TORRE DE SOM AWS-T1W-02 BIVOLT BLUETOOTH | H19: =VLOOKUP(F19,'[1]DESCRICAO PRODUTO'!$A:$C,3,0) -> T1W
A20: 040125-0024-01 | B20: CX DE EMBALAGEM INDIVIDUAL T2W | C20: 100 | D20: EMBALAGEM | E20: CAIXA INDIVIDUAL | F20: 5016-01 | G20: =VLOOKUP(F20,'[1]DESCRICAO PRODUTO'!$A:$C,2,0) -> TORRE DE SOM AWS-T2W-02 BIVOLT BLUETOOTH | H20: =VLOOKUP(F20,'[1]DESCRICAO PRODUTO'!$A:$C,3,0) -> T2W
A21: 040125-0028-01 | B21: CX DE EMBALAGEM INDIVIDUAL TM-2200 | C21: 100 | D21: EMBALAGEM | E21: CAIXA INDIVIDUAL | F21: 2501-01 | G21: =VLOOKUP(F21,'[1]DESCRICAO PRODUTO'!$A:$C,2,0) -> TORRE DE SOM TM2200 BIV | H21: =VLOOKUP(F21,'[1]DESCRICAO PRODUTO'!$A:$C,3,0) -> TM2200
A22: 040122-0015-01 | B22: CX DE EMBALAGEM INDIVIDUAL ANDROID 32 | C22: 300 | D22: EMBALAGEM | E22: CAIXA INDIVIDUAL | F22: 8832-01 | G22: =VLOOKUP(F22,'[1]DESCRICAO PRODUTO'!$A:$C,2,0) -> TV 32 ANDROID BORD INF AWS-TV-32-BL-02-A | H22: =VLOOKUP(F22,'[1]DESCRICAO PRODUTO'!$A:$C,3,0) -> TV 32 ANDROID
A23: 040122-0016-01 | B23: CX DE EMBALAGEM INDIVIDUAL ANDROID 43" | C23: 150 | D23: EMBALAGEM | E23: CAIXA INDIVIDUAL | F23: 8843-03 | G23: =VLOOKUP(F23,'[1]DESCRICAO PRODUTO'!$A:$C,2,0) -> TV 43 ANDROID BORD INF AWS-TV-43-BL-02-A | H23: =VLOOKUP(F23,'[1]DESCRICAO PRODUTO'!$A:$C,3,0) -> TV 43 ANDROID
A24: 040122-0002-01 | B24: CX DE EMBALAGEM INDIVIDUAL TV43" | C24: 150 | D24: EMBALAGEM | E24: CAIXA INDIVIDUAL | F24: 4302-01 | G24: =VLOOKUP(F24,'[1]DESCRICAO PRODUTO'!$A:$C,2,0) -> TV 43 SMART AWS-TV-43-BL-01 | H24: =VLOOKUP(F24,'[1]DESCRICAO PRODUTO'!$A:$C,3,0) -> TV 43 BL
A25: 040122-0017-01 | B25: CX DE EMBALAGEM INDIVIDUAL ANDROID 50 | C25: 130 | D25: EMBALAGEM | E25: CAIXA INDIVIDUAL | F25: 5026-02 | G25: =VLOOKUP(F25,'[1]DESCRICAO PRODUTO'!$A:$C,2,0) -> TV 50 ANDROID BORD INF AWS-TV-50-BL-02-A | H25: =VLOOKUP(F25,'[1]DESCRICAO PRODUTO'!$A:$C,3,0) -> TV 50 ANDROID
A26: 040122-0018-01 | B26: CX DE EMBALAGEM INDIVIDUAL TV55" - TEMP | C26: 135 | D26: EMBALAGEM | E26: CAIXA INDIVIDUAL | F26: 5504-01 | G26: =VLOOKUP(F26,'[1]DESCRICAO PRODUTO'!$A:$C,2,0) -> TV 55 ANDROID AWS-TV-55-BL-01 | H26: =VLOOKUP(F26,'[1]DESCRICAO PRODUTO'!$A:$C,3,0) -> TV 55 ANDROID

Sheet CRONOGRAMA DE ENTREGA
A1: STATUS | B1: (Tudo)
A3: Soma de SOLICITADO | C3: Rótulos de Coluna
A4: DESTINO | B4: TIPO | C4: TBC | D4: 46091 | E4: 46104 | F4: 46106 | G4: 46107 | H4: 46108 | I4: 46122 | J4: 46125 | K4: 46136 | L4: 46160 | M4: 46163 | N4: 46167 | O4: 46168 | P4: 46169 | Q4: 46192 | R4: 46204 | S4: 46218 | T4: 46245 | U4: 46247 | V4: 46253 | W4: 46258 | X4: 46261 | Y4: 46265 | Z4: 46269 | AA4: 46275 | AB4: 46286 | AC4: (vazio) | AD4: Total Geral
A5: BAHIA | B5: EMBALAGEM | C5: 1213 | D5: 173 | E5: 1686 | G5: 3232 | H5: 3329 | I5: 1783 | J5: 1600 | K5: 1936 | L5: 1486 | O5: 2062 | R5: 2550 | T5: 965 | U5: 4707 | V5: 1117 | W5: 7761 | X5: 2000 | Z5: 4502 | AA5: 1421 | AB5: 1332 | AC5: 2323 | AD5: 47178
B6: INSUMO | D6: 346 | F6: 3432 | H6: 1143 | I6: 2208 | J6: 3200 | K6: 1042 | M6: 2880 | N6: 344 | O6: 1344 | T6: 6364 | U6: 3907 | V6: 412 | W6: 11649 | Y6: 2944 | AC6: 1226 | AD6: 42441
A7: CAJAMAR | B7: INSUMO | K7: 12 | AD7: 12
A8: JTD TRANSPORTES | B8: EMBALAGEM | L8: 1757 | P8: 2000 | Q8: 1300 | R8: 500 | T8: 535 | U8: 1268 | V8: 2785 | W8: 464 | Z8: 300 | AB8: 1310 | AC8: 2881 | AD8: 15100
B9: INSUMO | Q9: 400 | S9: 4500 | T9: 148 | U9: 136 | V9: 590 | W9: 292 | Y9: 1410 | AC9: 306 | AD9: 7782
A10: Total Geral | C10: 1213 | D10: 519 | E10: 1686 | F10: 3432 | G10: 3232 | H10: 4472 | I10: 3991 | J10: 4800 | K10: 2990 | L10: 3243 | M10: 2880 | N10: 344 | O10: 3406 | P10: 2000 | Q10: 1700 | R10: 3050 | S10: 4500 | T10: 8012 | U10: 10018 | V10: 4904 | W10: 20166 | X10: 2000 | Y10: 4354 | Z10: 4802 | AA10: 1421 | AB10: 2642 | AC10: 6736 | AD10: 112513

Sheet RESUMO- STATUS DE ENVIO
A3: SOLICITAÇÃO | B3: SOLICITANTE | C3: DESTINO | D3: SOLICITADO. | E3: ENVIADO. | F3: PENDENTE.
A4: 1 | B4: VANESSA | C4: BAHIA | D4: 33359 | E4: 26119 | F4: -7240
A5: 2 | B5: TAIMON | C5: BAHIA | D5: 519 | E5: 519 | F5: 0
A6: 3 | B6: VANESSA | C6: BAHIA | D6: 12585 | E6: 12426 | F6: -159
A7: 4 | B7: MARCELA | C7: JTD TRANSPORTES | D7: 3700 | E7: 3700 | F7: 0
A8: 5 | B8: MARCIO | C8: CAJAMAR | D8: 12 | E8: 12 | F8: 0
A9: 6 | B9: JAQUELINE | C9: BAHIA | D9: 467 | E9: 434 | F9: -33
A10: 7 | B10: MARCELA | C10: JTD TRANSPORTES | D10: 257 | E10: 257 | F10: 0
A11: 8 | B11: HERISON | C11: JTD TRANSPORTES | D11: 2000 | E11: 2000 | F11: 0
A12: 9 | B12: VANESSA | C12: BAHIA | D12: 14097 | E12: 8307 | F12: -5790
A13: 10 | B13: JOYCE | C13: JTD TRANSPORTES | D13: 12425 | E13: 5472 | F13: -6953
A14: 11 | B14: HERISON | C14: JTD TRANSPORTES | D14: 4500 | E14: 4500 | F14: 0
A15: 12 | B15: VANESSA | C15: BAHIA | D15: 3390 | E15: 3300 | F15: -90
... A18: 15 | B18: VANESSA/ CD | C18: BAHIA | D18: 12933 | E18: 4541 | F18: -8392
A19: (vazio) | B19: (vazio) | C19: (vazio)
A20: Total Geral | D20: 112513 | E20: 81521 | F20: -30992
